<?xml version="1.0"?>
<robot name="xacro_macros" xmlns:xacro="http://ros.org/wiki/xacro">

<xacro:macro name="wheel" params="prefix reflect">

    <link name="${prefix}_wheel">

      <collision name="collision">
        <origin xyz="0 0 0" rpy="0 0 1.57" />
        <geometry>
          <cylinder radius="0.1" length="0.05"/>
        </geometry>
      </collision>

      <visual name="${prefix}_wheel_visual">
        <origin xyz="0.47 -0.85 0" rpy="0 0 1.57" />
        <geometry>
            <mesh filename="package://robot_description/meshes/wheel.stl" scale="0.01 0.01 0.01"/>
        </geometry>
      </visual>

      <inertial>
		  <origin xyz="0 0 0" rpy="0 0 1.57"/>
		  <mass value="5"/>
		  <cylinder_inertia m="5" r="0.1" h="0.05"/>
		  <inertia
		    ixx="1.0" ixy="0.0" ixz="0.0"
		    iyy="1.0" iyz="0.0"
		    izz="1.0"/>
      </inertial>

    </link>

    <joint type="continuous" name="${prefix}_wheel_hinge">
		<origin xyz="0.1 0.15 0" rpy="0 0 0"/>
		<child link="${prefix}_wheel"/>
		<parent link="chassis"/>
		<axis xyz="0 1 0" rpy="0 0 0"/>
		<limit effort="100" velocity="100"/>
		<joint_properties damping="0.0" friction="0.0"/>
    </joint>

  </xacro:macro>

</robot>
