<?xml version='1.0'?>

<robot name="robot" xmlns:xacro="http://www.ros.org/wiki/xacro">



  <xacro:include filename="$(find robot_description)/urdf/common_properties.xacro" />
  <xacro:include filename="$(find robot_description)/urdf/romi.gazebo.xacro" />
  <xacro:include filename="$(find robot_description)/urdf/macros.xacro" />
 

	<link name="base_footprint"/>

    <joint name="base_joint" type="fixed">
      <parent link="base_footprint"/>
      <child link="chassis"/>
      <origin xyz="0.0 0.0 0.010" rpy="0 0 0"/>
    </joint>

  <link name='chassis'>
    <pose>-1.3 -0.8 -0.88 1.57 0 1.65</pose>

    <inertial>
      <mass value="10.0"/>
      <origin xyz="0 0 0" rpy="1.57 0 1.57"/>
      <inertia
          ixx="0.5" ixy="0" ixz="0"
          iyy="1.0" iyz="0"
          izz="0.1"
      />
    </inertial>

    <collision name='collision'>
      <geometry>
        <cylinder length="0.73" radius="0.49"/>
      </geometry>
    </collision>

    <visual name='chassis_visual'>
		
      <origin xyz="-1.3 -0.8 -0.88" rpy="1.57 0 1.65"/>
      <geometry>
        <mesh filename="package://robot_description/meshes/chassis.stl" scale="0.01 0.01 0.01"/>
      </geometry>
    </visual>


    <collision name='caster_collision'>
       <origin xyz="1.05 -0.32 -0.15" rpy="-1.57 0 0"/>
      <geometry>
        <sphere radius="0.05"/>
      </geometry>
      <surface>
        <friction>
          <ode>
            <mu>0</mu>
            <mu2>0</mu2>
            <slip1>1.0</slip1>
            <slip2>1.0</slip2>
          </ode>
        </friction>
      </surface>
    </collision>

    <visual name='caster_visual'>
      <origin xyz="1.05 -0.32 -0.15" rpy="-1.57 0 0"/>
      <geometry>
       <mesh filename="package://robot_description/meshes/front-caster.stl" scale="0.01 0.01 0.01"/>
      </geometry>
    </visual>
  </link>

  <joint type="continuous" name="left_wheel_hinge">
    <origin xyz="0.1 -0.2 0" rpy="0 0 0"/>
    <child link="left_wheel"/>
    <parent link="chassis"/>
    <axis xyz="0 1 0" rpy="0 0 0"/>
    <limit effort="100" velocity="100"/>
    <joint_properties damping="0.0" friction="0.0"/>
  </joint>

  <link name="left_wheel">
    <!--origin xyz="0.1 0.13 0.1" rpy="0 1.5707 1.5707"/-->
    <collision name="collision">
      <origin xyz="0 0 0" rpy="0 0 1.57"/>
      <geometry>
        <cylinder radius="0.1" length="0.05"/>
      </geometry>
    </collision>

    <visual name="left_wheel_visual">
      <origin xyz="0 0 0" rpy="0 0 1.57"/>
      <geometry>
         <mesh filename="package://robot_description/meshes/wheel.stl" scale="0.01 0.01 0.01"/>
      </geometry>
    </visual>

    <inertial>
      <origin xyz="0 0 0" rpy="0 0 1.57"/>
      <mass value="5"/>
      <cylinder_inertia m="5" r="0.1" h="0.05"/>
      <inertia
        ixx="1.0" ixy="0.0" ixz="0.0"
        iyy="1.0" iyz="0.0"
        izz="1.0"/>
    </inertial>
  </link>

  <joint type="continuous" name="right_wheel_hinge">
    <origin xyz="0.1 -0.4 0" rpy="0 0 0"/>
    <child link="right_wheel"/>
    <parent link="chassis"/>
    <axis xyz="0 1 0" rpy="0 0 0"/>
    <limit effort="100" velocity="100"/>
    <joint_properties damping="0.0" friction="0.0"/>
  </joint>

  <link name="right_wheel">
    <!--origin xyz="0.1 -0.13 0.1" rpy="0 1.5707 1.5707"/-->
    <collision name="collision">
      <origin xyz="0 0 0" rpy="0 0 1.57"/>
      <geometry>
        <cylinder radius="0.1" length="0.05"/>
      </geometry>
    </collision>

    <visual name="right_wheel_visual">
      <origin xyz="0 0 0" rpy="0 0 1.57"/>
      <geometry>
         <mesh filename="package://robot_description/meshes/wheel.stl" scale="0.01 0.01 0.01"/>
      </geometry>
    </visual>

    <inertial>
      <origin xyz="0 0 0" rpy="0 0 1.57"/>
      <mass value="5"/>
      <cylinder_inertia m="5" r="0.1" h="0.05"/>
      <inertia
        ixx="1.0" ixy="0.0" ixz="0.0"
        iyy="1.0" iyz="0.0"
        izz="1.0"/>
    </inertial>
  </link>



</robot>
